nohup: ignoring input
/usr/local/lib/python3.6/dist-packages/torch/optim/lr_scheduler.py:134: UserWarning: Detected call of `lr_scheduler.step()` before `optimizer.step()`. In PyTorch 1.1.0 and later, you should call them in the opposite order: `optimizer.step()` before `lr_scheduler.step()`.  Failure to do this will result in PyTorch skipping the first value of the learning rate schedule. See more details at https://pytorch.org/docs/stable/optim.html#how-to-adjust-learning-rate
  "https://pytorch.org/docs/stable/optim.html#how-to-adjust-learning-rate", UserWarning)
/usr/local/lib/python3.6/dist-packages/torch/nn/_reduction.py:42: UserWarning: size_average and reduce args will be deprecated, please use reduction='sum' instead.
  warnings.warn(warning.format(ret))
Traceback (most recent call last):
  File "train_ssd.py", line 393, in <module>
    device=DEVICE, debug_steps=args.debug_steps, epoch=epoch)
  File "train_ssd.py", line 143, in train
    images = images.to(device)
  File "/usr/local/lib/python3.6/dist-packages/torch/utils/data/_utils/signal_handling.py", line 66, in handler
    _error_if_any_worker_fails()
RuntimeError: DataLoader worker (pid 134481) is killed by signal: Killed. 
processing/connection.py", line 414, in _poll
    r = wait([self], timeout)
  File "/usr/lib/python3.6/multiprocessing/connection.py", line 911, in wait
    ready = selector.select(timeout)
  File "/usr/lib/python3.6/selectors.py", line 376, in select
    fd_event_list = self._poll.poll(timeout)
  File "/usr/local/lib/python3.6/dist-packages/torch/utils/data/_utils/signal_handling.py", line 66, in handler
    _error_if_any_worker_fails()
RuntimeError: DataLoader worker (pid 140936) is killed by signal: Killed. 

The above exception was the direct cause of the following exception:

Traceback (most recent call last):
  File "train_ssd.py", line 393, in <module>
    device=DEVICE, debug_steps=args.debug_steps, epoch=epoch)
  File "train_ssd.py", line 141, in train
    for i, data in enumerate(loader):
  File "/usr/local/lib/python3.6/dist-packages/torch/utils/data/dataloader.py", line 517, in __next__
    data = self._next_data()
  File "/usr/local/lib/python3.6/dist-packages/torch/utils/data/dataloader.py", line 1182, in _next_data
    idx, data = self._get_data()
  File "/usr/local/lib/python3.6/dist-packages/torch/utils/data/dataloader.py", line 1148, in _get_data
    success, data = self._try_get_data()
  File "/usr/local/lib/python3.6/dist-packages/torch/utils/data/dataloader.py", line 999, in _try_get_data
    raise RuntimeError('DataLoader worker (pid(s) {}) exited unexpectedly'.format(pids_str)) from e
RuntimeError: DataLoader worker (pid(s) 140936, 140960, 140984, 141008) exited unexpectedly
